[2025-03-16T17:46:02.208+0000] {taskinstance.py:1159} INFO - Dependencies all met for dep_context=non-requeueable deps ti=<TaskInstance: reddit_dag.reddit_extraction scheduled__2025-03-15T00:00:00+00:00 [queued]>
[2025-03-16T17:46:02.212+0000] {taskinstance.py:1159} INFO - Dependencies all met for dep_context=requeueable deps ti=<TaskInstance: reddit_dag.reddit_extraction scheduled__2025-03-15T00:00:00+00:00 [queued]>
[2025-03-16T17:46:02.212+0000] {taskinstance.py:1361} INFO - Starting attempt 2 of 2
[2025-03-16T17:46:02.219+0000] {taskinstance.py:1382} INFO - Executing <Task(PythonOperator): reddit_extraction> on 2025-03-15 00:00:00+00:00
[2025-03-16T17:46:02.224+0000] {standard_task_runner.py:57} INFO - Started process 56 to run task
[2025-03-16T17:46:02.227+0000] {standard_task_runner.py:84} INFO - Running: ['airflow', 'tasks', 'run', 'reddit_dag', 'reddit_extraction', 'scheduled__2025-03-15T00:00:00+00:00', '--job-id', '8', '--raw', '--subdir', 'DAGS_FOLDER/reddit_dag.py', '--cfg-path', '/tmp/tmpzaowea7z']
[2025-03-16T17:46:02.229+0000] {standard_task_runner.py:85} INFO - Job 8: Subtask reddit_extraction
[2025-03-16T17:46:02.261+0000] {task_command.py:416} INFO - Running <TaskInstance: reddit_dag.reddit_extraction scheduled__2025-03-15T00:00:00+00:00 [running]> on host 88d4374c5b3c
[2025-03-16T17:46:02.310+0000] {taskinstance.py:1662} INFO - Exporting env vars: AIRFLOW_CTX_DAG_EMAIL='rajagopalanr0210@gmail.com' AIRFLOW_CTX_DAG_OWNER='Raja' AIRFLOW_CTX_DAG_ID='reddit_dag' AIRFLOW_CTX_TASK_ID='reddit_extraction' AIRFLOW_CTX_EXECUTION_DATE='2025-03-15T00:00:00+00:00' AIRFLOW_CTX_TRY_NUMBER='2' AIRFLOW_CTX_DAG_RUN_ID='scheduled__2025-03-15T00:00:00+00:00'
[2025-03-16T17:46:02.312+0000] {logging_mixin.py:151} WARNING - Version 7.7.1 of praw is outdated. Version 7.8.1 was released Friday October 25, 2024.
[2025-03-16T17:46:02.314+0000] {reddit_etl.py:13} INFO - Connect to Reddit:
[2025-03-16T17:46:03.566+0000] {reddit_pipeline.py:15} ERROR - Error in reddit_extraction: [Errno 21] Is a directory: '/opt/airflow/data/output'
[2025-03-16T17:46:03.567+0000] {taskinstance.py:1937} ERROR - Task failed with exception
Traceback (most recent call last):
  File "/home/airflow/.local/lib/python3.9/site-packages/airflow/operators/python.py", line 192, in execute
    return_value = self.execute_callable()
  File "/home/airflow/.local/lib/python3.9/site-packages/airflow/operators/python.py", line 209, in execute_callable
    return self.python_callable(*self.op_args, **self.op_kwargs)
  File "/opt/airflow/pipelines/reddit_pipeline.py", line 13, in reddit_extraction
    load_data_to_csv(post_df,OUTPUT_PATH)
  File "/opt/airflow/etls/reddit_etl.py", line 49, in load_data_to_csv
    data.to_csv(path, index=False)
  File "/home/airflow/.local/lib/python3.9/site-packages/pandas/core/generic.py", line 3902, in to_csv
    return DataFrameRenderer(formatter).to_csv(
  File "/home/airflow/.local/lib/python3.9/site-packages/pandas/io/formats/format.py", line 1152, in to_csv
    csv_formatter.save()
  File "/home/airflow/.local/lib/python3.9/site-packages/pandas/io/formats/csvs.py", line 247, in save
    with get_handle(
  File "/home/airflow/.local/lib/python3.9/site-packages/pandas/io/common.py", line 863, in get_handle
    handle = open(
IsADirectoryError: [Errno 21] Is a directory: '/opt/airflow/data/output'
[2025-03-16T17:46:03.579+0000] {taskinstance.py:1400} INFO - Marking task as FAILED. dag_id=reddit_dag, task_id=reddit_extraction, execution_date=20250315T000000, start_date=20250316T174602, end_date=20250316T174603
[2025-03-16T17:46:03.589+0000] {warnings.py:109} WARNING - /home/airflow/.local/lib/python3.9/site-packages/airflow/utils/email.py:154: RemovedInAirflow3Warning: Fetching SMTP credentials from configuration variables will be deprecated in a future release. Please set credentials using a connection instead.
  send_mime_email(e_from=mail_from, e_to=recipients, mime_msg=msg, conn_id=conn_id, dryrun=dryrun)

[2025-03-16T17:46:03.590+0000] {configuration.py:1068} WARNING - section/key [smtp/smtp_user] not found in config
[2025-03-16T17:46:03.590+0000] {email.py:270} INFO - Email alerting: attempt 1
[2025-03-16T17:46:03.594+0000] {configuration.py:1068} WARNING - section/key [smtp/smtp_user] not found in config
[2025-03-16T17:46:03.594+0000] {email.py:270} INFO - Email alerting: attempt 1
[2025-03-16T17:46:03.594+0000] {taskinstance.py:2007} ERROR - Failed to send email to: rajagopalanr0210@gmail.com
Traceback (most recent call last):
  File "/home/airflow/.local/lib/python3.9/site-packages/airflow/models/taskinstance.py", line 1518, in _run_raw_task
    self._execute_task_with_callbacks(context, test_mode, session=session)
  File "/home/airflow/.local/lib/python3.9/site-packages/airflow/models/taskinstance.py", line 1681, in _execute_task_with_callbacks
    result = self._execute_task(context, task_orig)
  File "/home/airflow/.local/lib/python3.9/site-packages/airflow/models/taskinstance.py", line 1744, in _execute_task
    result = execute_callable(context=context, **execute_callable_kwargs)
  File "/home/airflow/.local/lib/python3.9/site-packages/airflow/operators/python.py", line 192, in execute
    return_value = self.execute_callable()
  File "/home/airflow/.local/lib/python3.9/site-packages/airflow/operators/python.py", line 209, in execute_callable
    return self.python_callable(*self.op_args, **self.op_kwargs)
  File "/opt/airflow/pipelines/reddit_pipeline.py", line 13, in reddit_extraction
    load_data_to_csv(post_df,OUTPUT_PATH)
  File "/opt/airflow/etls/reddit_etl.py", line 49, in load_data_to_csv
    data.to_csv(path, index=False)
  File "/home/airflow/.local/lib/python3.9/site-packages/pandas/core/generic.py", line 3902, in to_csv
    return DataFrameRenderer(formatter).to_csv(
  File "/home/airflow/.local/lib/python3.9/site-packages/pandas/io/formats/format.py", line 1152, in to_csv
    csv_formatter.save()
  File "/home/airflow/.local/lib/python3.9/site-packages/pandas/io/formats/csvs.py", line 247, in save
    with get_handle(
  File "/home/airflow/.local/lib/python3.9/site-packages/pandas/io/common.py", line 863, in get_handle
    handle = open(
IsADirectoryError: [Errno 21] Is a directory: '/opt/airflow/data/output'

During handling of the above exception, another exception occurred:

Traceback (most recent call last):
  File "/home/airflow/.local/lib/python3.9/site-packages/airflow/models/taskinstance.py", line 2420, in email_alert
    send_email(task.email, subject, html_content)
  File "/home/airflow/.local/lib/python3.9/site-packages/airflow/utils/email.py", line 80, in send_email
    return backend(
  File "/home/airflow/.local/lib/python3.9/site-packages/airflow/utils/email.py", line 154, in send_email_smtp
    send_mime_email(e_from=mail_from, e_to=recipients, mime_msg=msg, conn_id=conn_id, dryrun=dryrun)
  File "/home/airflow/.local/lib/python3.9/site-packages/airflow/utils/email.py", line 272, in send_mime_email
    smtp_conn = _get_smtp_connection(smtp_host, smtp_port, smtp_timeout, smtp_ssl)
  File "/home/airflow/.local/lib/python3.9/site-packages/airflow/utils/email.py", line 316, in _get_smtp_connection
    return smtplib.SMTP(host=host, port=port, timeout=timeout)
  File "/usr/local/lib/python3.9/smtplib.py", line 255, in __init__
    (code, msg) = self.connect(host, port)
  File "/usr/local/lib/python3.9/smtplib.py", line 341, in connect
    self.sock = self._get_socket(host, port, self.timeout)
  File "/usr/local/lib/python3.9/smtplib.py", line 312, in _get_socket
    return socket.create_connection((host, port), timeout,
  File "/usr/local/lib/python3.9/socket.py", line 844, in create_connection
    raise err
  File "/usr/local/lib/python3.9/socket.py", line 832, in create_connection
    sock.connect(sa)
ConnectionRefusedError: [Errno 111] Connection refused

During handling of the above exception, another exception occurred:

Traceback (most recent call last):
  File "/home/airflow/.local/lib/python3.9/site-packages/airflow/models/taskinstance.py", line 2005, in handle_failure
    self.email_alert(error, task)
  File "/home/airflow/.local/lib/python3.9/site-packages/airflow/models/taskinstance.py", line 2422, in email_alert
    send_email(task.email, subject, html_content_err)
  File "/home/airflow/.local/lib/python3.9/site-packages/airflow/utils/email.py", line 80, in send_email
    return backend(
  File "/home/airflow/.local/lib/python3.9/site-packages/airflow/utils/email.py", line 154, in send_email_smtp
    send_mime_email(e_from=mail_from, e_to=recipients, mime_msg=msg, conn_id=conn_id, dryrun=dryrun)
  File "/home/airflow/.local/lib/python3.9/site-packages/airflow/utils/email.py", line 272, in send_mime_email
    smtp_conn = _get_smtp_connection(smtp_host, smtp_port, smtp_timeout, smtp_ssl)
  File "/home/airflow/.local/lib/python3.9/site-packages/airflow/utils/email.py", line 316, in _get_smtp_connection
    return smtplib.SMTP(host=host, port=port, timeout=timeout)
  File "/usr/local/lib/python3.9/smtplib.py", line 255, in __init__
    (code, msg) = self.connect(host, port)
  File "/usr/local/lib/python3.9/smtplib.py", line 341, in connect
    self.sock = self._get_socket(host, port, self.timeout)
  File "/usr/local/lib/python3.9/smtplib.py", line 312, in _get_socket
    return socket.create_connection((host, port), timeout,
  File "/usr/local/lib/python3.9/socket.py", line 844, in create_connection
    raise err
  File "/usr/local/lib/python3.9/socket.py", line 832, in create_connection
    sock.connect(sa)
ConnectionRefusedError: [Errno 111] Connection refused
[2025-03-16T17:46:03.601+0000] {standard_task_runner.py:104} ERROR - Failed to execute job 8 for task reddit_extraction ([Errno 21] Is a directory: '/opt/airflow/data/output'; 56)
[2025-03-16T17:46:03.608+0000] {local_task_job_runner.py:228} INFO - Task exited with return code 1
[2025-03-16T17:46:03.618+0000] {taskinstance.py:2778} INFO - 0 downstream tasks scheduled from follow-on schedule check
